2015-03-25 20:45:52
Traceback (most recent call last):
  File "/Users/wbond/Library/Application Support/Sublime Text 3/Packages/SFTP/sftp/threads.py", line 15, in run_with_except_hook
  File "/Users/wbond/Library/Application Support/Sublime Text 3/Packages/SFTP/sftp/commands.py", line 1174, in run
  File "./os.py", line 258, in makedirs
  File "./os.py", line 258, in makedirs
  File "./os.py", line 269, in makedirs
OSError: [Errno 45] Operation not supported: '/home/maurice'
2017-06-22 18:07:51
Traceback (most recent call last):
  File "/Users/wbond/Library/Application Support/Sublime Text 3/Packages/SFTP/sftp/ftp_transport.py", line 208, in handle_ftp_error
  File "/Users/wbond/Library/Application Support/Sublime Text 3/Packages/SFTP/sftp/ftp_transport.py", line 633, in do_ls
  File "/Users/wbond/Library/Application Support/Sublime Text 3/Packages/SFTP/sftp/ftplib2.py", line 574, in retrlines
  File "/Users/wbond/Library/Application Support/Sublime Text 3/Packages/SFTP/sftp/ftplib2.py", line 507, in transfercmd
  File "/Users/wbond/Library/Application Support/Sublime Text 3/Packages/SFTP/sftp/ftplib2.py", line 465, in ntransfercmd
  File "./python3.3/socket.py", line 435, in create_connection
  File "./python3.3/socket.py", line 426, in create_connection
ConnectionRefusedError: [Errno 61] Connection refused

During handling of the above exception, another exception occurred:

Traceback (most recent call last):
  File "/Users/wbond/Library/Application Support/Sublime Text 3/Packages/SFTP/sftp/threads.py", line 16, in run_with_except_hook
  File "/Users/wbond/Library/Application Support/Sublime Text 3/Packages/SFTP/sftp/threads.py", line 119, in handler
  File "/Users/wbond/Library/Application Support/Sublime Text 3/Packages/SFTP/sftp/commands.py", line 355, in run
  File "/Users/wbond/Library/Application Support/Sublime Text 3/Packages/SFTP/sftp/commands.py", line 510, in do_operation
  File "/Users/wbond/Library/Application Support/Sublime Text 3/Packages/SFTP/sftp/file_transfer.py", line 47, in handler
  File "/Users/wbond/Library/Application Support/Sublime Text 3/Packages/SFTP/sftp/file_transfer.py", line 502, in listr
  File "/Users/wbond/Library/Application Support/Sublime Text 3/Packages/SFTP/sftp/file_transfer.py", line 47, in handler
  File "/Users/wbond/Library/Application Support/Sublime Text 3/Packages/SFTP/sftp/file_transfer.py", line 465, in list
  File "/Users/wbond/Library/Application Support/Sublime Text 3/Packages/SFTP/sftp/ftp_transport.py", line 662, in ls
  File "/Users/wbond/Library/Application Support/Sublime Text 3/Packages/SFTP/sftp/ftp_transport.py", line 635, in ls
  File "/Users/wbond/Library/Application Support/Sublime Text 3/Packages/SFTP/sftp/ftp_transport.py", line 388, in handle_ftp_error
SFTP.sftp.errors.ConnectionError: Connection refused
